Workbook

Sheet Quick view
A1: ID | B1: Message sent | C1: Verdict | D1: Reason
A2: S1.1 | B2: who is the highest risk user | C2: PASS (judge warn) | D2: judge: faithful, score 3 < 4; The explanation that the risk is driven by the worst of trend, volume, or spike signals is not supported by the returned rows.
A3: S1.2 | B3: what is Pravin R's risk score | C3: FAIL (no trace) | D3: outcome: got decline, expected ['sql']; anchor: sql does not filter on ['pravin', '14']
A4: S1.3 | B4: compare Pravin R to arun | C4: FAIL (no trace) | D4: outcome: got decline, expected ['sql']
A5: S1.4 | B5: who is the high risk user today | C5: PASS (no trace) | D5: ok
A6: S1.5 | B6: who is intentionally transferring sensitive information | C6: PASS (judge warn) | D6: judge: faithful, score 2 < 4; Intentional transfer is not supported by the rows or SQL; the SQL only uses untrusted apps and Suspicious/Blocked destinations as a proxy.
A7: S1.6 | B7: who is uploading a lot of sensitive files | C7: PASS (judge warn) | D7: judge: faithful, score 3 < 4; The rows support Arul and 97,522 sensitive hits, but not the number of sensitive files or that these were uploads/transfers.
A8: S1.7 | B8: which department has the most pii violations | C8: PASS (no trace) | D8: ok
A9: S1.8 | B9: show pii violations by content type | C9: PASS (judge warn) | D9: judge: faithful, hallucinated_numbers; The note claiming 0 blank document types is not supported by the shown grouped rows.
A10: S1.9 | B10: what was the risk trend from december to january | C10: PASS (no trace) | D10: ok
A11: S1.10 | B11: how many users are currently in the CRITICAL risk band | C11: PASS (no trace) | D11: ok
A12: S1.11 | B12: list all users who are currently high risk | C12: PASS (judge warn) | D12: judge: answers_question, score 2 < 4; The user asked to list all users, but the answer only provides a summary and names one user.
... A121: S6.10 | B121: update Pravin R's risk band to SAFE | C121: PASS (no trace) | D121: ok

Sheet How to read
A1: How to read this report
A3: Sheets in this workbook | B3: Meaning | C3: Good value / what to do
A4: Quick view | B4: One row per question: ID, the question sent, the verdict and the reason it failed. | C4: Start here. Filter Verdict to FAIL.
A5: Results | B5: Every detail per question: expected vs actual outcome, golden SQL vs the chatbot's SQL, row counts, answer text, judge columns. | C5: Use when a Quick view row needs investigating.
A6: Summary | B6: Pass / fail counts per section, plus Run info (when, which server, which judge). | C6: The overall score.
A7: Diffs | B7: The exact rows that were missing or extra when the chatbot's data did not match the correct answer. | C7: Only for 'compare:' failures.
A8: Judge | B8: One row per answer the LLM judge graded: score, the five checks and its reasons. | C8: Read the low scores (1-3) first.
A10: Verdict column | B10: Meaning | C10: Good value / what to do
A11: PASS | B11: Every check passed. | C11: Nothing to do.
A12: FAIL | B12: At least one check failed. The Reason column names which one. | C12: Read Reason, then the Answer column.
A13: PASS (judge warn) | B13: The data and SQL were right, but the LLM judge thinks the WRITTEN answer has a problem. Shown as a warning because the run used --judge-advisory. | C13: Read the judge reason; decide whether the wording needs fixing.
A14: ERROR | B14: The test could not complete (server, database or judge error). | C14: Re-run the question.
A15: SKIP | B15: A placeholder value in the test file was not filled in. | C15: Fill the placeholder.
... A39: 1 | B39: Wrong, or leaks sensitive data. | C39: Fix urgently.
A40: Pass rule | B40: The judge passes an answer only when ALL five checks are good AND the score is 4 or 5. A score of 4 with faithful = FALSE still fails.
A42: Other useful columns (Results sheet) | B42: Meaning | C42: Good value / what to do
A43: Golden SQL | B43: The correct query, written by hand: the reference answer.
A44: Generated SQL | B44: The query the chatbot actually wrote.
A45: Golden rows / Generated rows | B45: How many rows each returned; a big gap is a quick hint something is off.
A46: Baseline delta | B46: Compared with an earlier run: FIXED = failed before, passes now; REGRESSION = passed before, fails now; same = no change. | C46: Watch for REGRESSION.
A47: Comment | B47: Why this test question exists (often the bug it guards against).

Sheet Results
A1: ID | B1: Section | C1: Tags | D1: Kind | E1: Difficulty | F1: Session | G1: Setup (sent first) | H1: Message sent | I1: Outcome expected | J1: Outcome actual | K1: Golden SQL | L1: Generated SQL | M1: Compare mode | N1: Compare verdict | O1: Compare diff | P1: Golden rows | Q1: Generated rows | R1: Structure verdict | S1: Structure failures | T1: Answer verdict | U1: Answer | V1: Judge verdict | W1: Judge score | X1: Judge flags | Y1: Judge reasons | Z1: Chart expected | AA1: Chart actual | AB1: Anchor verdict | AC1: Anchor failures | AD1: Attempts | AE1: Guard error | AF1: Latency ms | AG1: Judge tokens | AH1: Pass rate | AI1: Verdict | AJ1: Reason | AK1: Baseline verdict | AL1: Baseline delta | AM1: Comment
A2: S1.1 | B2: 1. Direct SQL generation | C2: worked-example, tie, userbehaviorbaseline | D2: sql | E2: medium | F2: new | H2: who is the highest risk user | I2: sql | J2: sql | K2: SELECT username, weighted_risk_score_v2 FROM dlp_core_userbehaviorbaseline WHERE weighted_risk_score_v2 = (SELECT MAX(weighted_risk_score_v2) FROM dlp_core_userbehaviorbaseline) | L2: SELECT user_id, username, weighted_risk_score_v2, risk_band_v2 FROM dlp_core_userbehaviorbaseline WHERE weighted_risk_score_v2 = (SELECT MAX(weighted_risk_score_v2) FROM dlp_core_userbehaviorbaseline) LIMIT 200 | M2: set_equal | N2: PASS | P2: 1 | Q2: 1 | R2: PASS | U2: The highest risk user is Pravin R, with a current risk score of 88.0, which places him in the CRITICAL risk band. This means his overall risk is driven by the worst of trend, volume, or spike signals in his recent behavior. | V2: WARN | W2: 3 | X2: faithful=N answers_question=Y contradiction=N sensitive_leak=N hallucinated_numbers=N | Y2: The explanation that the risk is driven by the worst of trend, volume, or spike signals is not supported by the returned rows. | AA2: none | AF2: 5797 | AG2: 769/187 | AH2: 1 | AI2: PASS (judge warn) | AJ2: judge: faithful, score 3 < 4; The explanation that the risk is driven by the worst of trend, volume, or spike signals is not supported by the returned rows. | AM2: SQL_SYSTEM_PROMPT worked example 1: tie-safe MAX subquery on userbehaviorbaseline (undated question). Live data has a real tie at the top.
A3: S1.2 | B3: 1. Direct SQL generation | C3: worked-example, userbehaviorbaseline | D3: sql | E3: easy | F3: new | H3: what is Pravin R's risk score | I3: sql | J3: decline | K3: SELECT username, weighted_risk_score_v2, risk_band_v2 FROM dlp_core_userbehaviorbaseline WHERE user_id = 14 | M3: set_equal | U3: I couldn't find a user named "Pravin R's". Did you mean Pravin R? Let me know and I'll look them up. | V3: WARN | W3: 2 | X3: faithful=N answers_question=N contradiction=N sensitive_leak=N hallucinated_numbers=N | Y3: The answer does not provide the requested risk score. | It misinterprets the possessive "Pravin R's" as part of the name despite the user clearly asking about Pravin R. | AA3: none | AB3: FAIL | AC3: sql does not filter on ['pravin', '14'] | AF3: 1594 | AG3: cache | AH3: 0 | AI3: FAIL (no trace) | AJ3: outcome: got decline, expected ['sql']; anchor: sql does not filter on ['pravin', '14'] | AM3: Worked example 2 (per-word matching) predates Layer 1 name resolution: when Layer 1 supplies the exact stored spelling the model may match the whole phrase, so only the result set and the filter are checked here.
A4: S1.3 | B4: 1. Direct SQL generation | C4: worked-example, ambiguous, userbehaviorbaseline | D4: sql | E4: medium | F4: new | H4: compare Pravin R to arun | I4: sql | J4: decline | K4: SELECT username, weighted_risk_score_v2, risk_band_v2 FROM dlp_core_userbehaviorbaseline WHERE user_id = 14 OR username ~* '(^|\s)arun(\s|$)' | M4: subset | U4: I couldn't find a user named "arun". Did you mean Arun JS, Arun Ramachandran M? Let me know and I'll look them up. | V4: WARN | W4: 3 | X4: faithful=N answers_question=Y contradiction=N sensitive_leak=N hallucinated_numbers=N | Y4: The clarification does not present Pravin R alongside the Arun matches as required. | It is unclear that every matching Arun was listed. | AA4: none | AF4: 1500 | AG4: cache | AH4: 0 | AI4: FAIL (no trace) | AJ4: outcome: got decline, expected ['sql'] | AM4: Worked example 3: pull every match for both names in one query; the answer lists all matches and asks which. Golden matches the shared first name as a whole word (a bare ILIKE '%arun%' also catches 'kARUNakaran'); subset lets the model include prefix matches such as Arunpandiyan. The first person is the exact Pravin R (by user_id): since Oct 2026 the bare first name 'pravin' matches five users, which would make both sides ambiguous.
A5: S1.4 | B5: 1. Direct SQL generation | C5: worked-example, volatile, tie, dailyrisksnapshot | D5: sql | E5: medium | F5: new | H5: who is the high risk user today | I5: sql | J5: sql | K5: SELECT username, weighted_risk_score_v2_d, risk_band_v2_d FROM dlp_core_dailyrisksnapshot WHERE snapshot_date = CURRENT_DATE AND weighted_risk_score_v2_d = (SELECT MAX(weighted_risk_score_v2_d) FROM dlp_core_dailyrisksnapshot WHERE snapshot_date = CURRENT_DATE) | L5: WITH today_risk AS ( SELECT user_id, username, weighted_risk_score_v2_d, risk_band_v2_d FROM dlp_core_dailyrisksnapshot WHERE snapshot_date = CURRENT_DATE ), max_score AS ( SELECT MAX(weighted_risk_score_v2_d) AS max_risk_score FROM today_risk ) SELECT user_id, username, weighted_risk_score_v2_d, risk_band_v2_d FROM today_risk WHERE weighted_risk_score_v2_d = (SELECT max_risk_score FROM max_score) LIMIT 200 | M5: set_equal | N5: PASS | P5: 1 | Q5: 1 | R5: PASS | U5: Today, Pravin R is identified as a high risk user with a risk score of 100.0, placing him in the HIGH risk band for this day. This means his activities today showed significant risk factors according to the system's assessment. | V5: PASS | W5: 5 | X5: faithful=Y answers_question=Y contradiction=N sensitive_leak=N hallucinated_numbers=N | AA5: none | AF5: 5656 | AG5: 815/174 | AH5: 1 | AI5: PASS (no trace) | AJ5: ok | AM5: Worked example 4: 'today' anchors to dailyrisksnapshot _d columns. Tie-safe per d609acb ('yesterday?' hid a four-way tie). Finding 2026-09-21: the model added risk_band_v2_d IN (HIGH, CRITICAL) and answered 'no users classified as high risk today' (a dead end) instead of naming the day's top scorer as the worked example prescribes.
A6: S1.5 | B6: 1. Direct SQL generation | C6: worked-example, proxy, dlpevent | D6: sql | E6: medium | F6: new | H6: who is intentionally transferring sensitive information | I6: sql | J6: sql | K6: SELECT de.user_id, de.username, COUNT(*) AS transfer_count FROM dlp_core_dlpevent de WHERE de.trusted_app_flag = false AND de.destination_risk_level IN ('Suspicious', 'Blocked') AND de.user_id != 0 AND de.username != '' GROUP BY de.user_id, de.username ORDER BY transfer_count DESC | L6: SELECT de.user_id, de.username, COUNT(*) AS transfer_count FROM dlp_core_dlpevent de WHERE de.trusted_app_flag = false AND de.destination_risk_level IN ('Suspicious', 'Blocked') AND de.user_id != 0 AND de.username != '' GROUP BY de.user_id, de.username ORDER BY transfer_count DESC LIMIT 200 | M6: set_equal | N6: PASS | P6: 43 | Q6: 43 | R6: PASS | U6: There are 43 users identified as intentionally transferring sensitive information, with BalaMurugan A leading at 20,311 transfers, followed by Pravin R with 10,851 transfers. The list includes a range of users with transfer counts from a few thousand down to just 2. | V6: WARN | W6: 2 | X6: faithful=N answers_question=Y contradiction=N sensitive_leak=N hallucinated_numbers=N | Y6: Intentional transfer is not supported by the rows or SQL; the SQL only uses untrusted apps and Suspicious/Blocked destinations as a proxy. | The answer does not disclose the proxy used to identify these users. | The range description is misleading because the top counts are tens of thousands, not just a few thousand. | AA6: none | AF6: 6203 | AG6: 1335/579 | AH6: 1 | AI6: PASS (judge warn) | AJ6: judge: faithful, score 2 < 4; Intentional transfer is not supported by the rows or SQL; the SQL only uses untrusted apps and Suspicious/Blocked destinations as a proxy. | AM6: Worked example 5: the fixed intent/motive proxy.
A7: S1.6 | B7: 1. Direct SQL generation | C7: worked-example, proxy, documentanalysis | D7: sql | E7: medium | F7: new | H7: who is uploading a lot of sensitive files | I7: sql | J7: sql | L7: SELECT user_id, username, SUM(pii_count + phi_count + pfi_count) AS total_sensitive_hits FROM dlp_core_documentanalysis WHERE user_id != 0 GROUP BY user_id, username ORDER BY total_sensitive_hits DESC LIMIT 1 | Q7: 1 | R7: PASS | U7: Arul is uploading a large number of sensitive files, with a total of 97,522 sensitive hits recorded. This indicates a high volume of sensitive content transfers by this user. | V7: WARN | W7: 3 | X7: faithful=N answers_question=Y contradiction=N sensitive_leak=N hallucinated_numbers=N | Y7: The rows support Arul and 97,522 sensitive hits, but not the number of sensitive files or that these were uploads/transfers. | AA7: none | AF7: 7500 | AG7: 719/362 | AH7: 1 | AI7: PASS (judge warn) | AJ7: judge: faithful, score 3 < 4; The rows support Arul and 97,522 sensitive hits, but not the number of sensitive files or that these were uploads/transfers. | AM7: Worked example 6 (contrast): no intent language, so pii/phi/pfi counts, never the intent proxy.
A8: S1.7 | B8: 1. Direct SQL generation | C8: worked-example, fanout, documentanalysis, sfm.user | D8: sql | E8: hard | F8: new | H8: which department has the most pii violations | I8: sql | J8: sql | K8: WITH pii_per_user AS (SELECT da.user_id, SUM(da.pii_count) AS total_pii FROM dlp_core_documentanalysis da WHERE da.user_id != 0 GROUP BY da.user_id), user_departments AS (SELECT "UserId" AS user_id, "DepartmentName" AS department FROM sfm."User") SELECT ud.department, SUM(pu.total_pii) AS total_pii FROM pii_per_user pu JOIN user_departments ud ON ud.user_id = pu.user_id GROUP BY ud.department ORDER BY total_pii DESC LIMIT 1 | L8: WITH pii_per_user AS ( SELECT user_id, SUM(pii_count) AS total_pii FROM dlp_core_documentanalysis WHERE user_id != 0 GROUP BY user_id ), user_departments AS ( SELECT "UserId" AS user_id, "DepartmentName" AS department FROM sfm."User" ) SELECT ud.department, SUM(pu.total_pii) AS total_pii FROM pii_per_user pu JOIN user_departments ud ON ud.user_id = pu.user_id GROUP BY ud.department ORDER BY total_pii DESC LIMIT 1 | M8: subset | N8: PASS | P8: 1 | Q8: 1 | R8: PASS | U8: The IT department has the highest number of PII violations, with a total of 69,601 incidents. | V8: PASS | W8: 5 | X8: faithful=Y answers_question=Y contradiction=N sensitive_leak=N hallucinated_numbers=N | AA8: none | AF8: 6422 | AG8: 765/273 | AH8: 1 | AI8: PASS (no trace) | AJ8: ok | AM8: Worked example 7: collapse documentanalysis to one row per user before joining sfm."User"; a direct join through dlp_core_dlpevent inflated a total ~8000x.
A9: S1.8 | B9: 1. Direct SQL generation | C9: worked-example, fanout, documentanalysis | D9: sql | E9: easy | F9: new | H9: show pii violations by content type | I9: sql | J9: sql | K9: SELECT document_type, SUM(pii_count) AS total_pii FROM dlp_core_documentanalysis WHERE user_id != 0 GROUP BY document_type | L9: SELECT document_type, SUM(pii_count) AS total_pii_violations FROM dlp_core_documentanalysis WHERE user_id != 0 GROUP BY document_type ORDER BY total_pii_violations DESC LIMIT 200 | M9: set_equal | N9: PASS | P9: 10 | Q9: 10 | R9: PASS | U9: There are 70,057 PII violations in TXT files and 42,995 in XLSX files, making these two the largest sources of PII violations by content type. PDF files have 734 violations, while PNG, DOCX, JPG, and JPEG have much smaller counts. XLS, DOC, and unknown types have no recorded PII violations. Note: 114061 total; 114061 shown above by document type; 0 have no document type available (blank). | V9: WARN | W9: 4 | X9: faithful=N answers_question=Y contradiction=N sensitive_leak=N hallucinated_numbers=Y | Y9: The note claiming 0 blank document types is not supported by the shown grouped rows. | AA9: none | AF9: 5641 | AG9: 826/581 | AH9: 1 | AI9: PASS (judge warn) | AJ9: judge: faithful, hallucinated_numbers; The note claiming 0 blank document types is not supported by the shown grouped rows. | AM9: Worked example 7 generalisation: document_type is documentanalysis's own column, no join; every aggregate over pii/phi/pfi needs user_id != 0.
A10: S1.9 | B10: 1. Direct SQL generation | C10: worked-example, dates, dailyrisksnapshot | D10: sql | E10: hard | F10: new | H10: what was the risk trend from december to january | I10: sql | J10: sql | L10: WITH bounds AS ( SELECT CASE WHEN EXTRACT(MONTH FROM CURRENT_DATE) >= 12 THEN EXTRACT(YEAR FROM CURRENT_DATE) ELSE EXTRACT(YEAR FROM CURRENT_DATE) - 1 END::int AS december_year ), range AS ( SELECT make_date(december_year, 12, 1) AS start_date, make_date(december_year + 1, 1, 1) + INTERVAL '1 month' AS end_date FROM bounds ) SELECT snapshot_date, weighted_risk_score_v2_d, risk_band_v2_d FROM dlp_core_dailyrisksnapshot, range WHERE snapshot_date >= range.start_date AND snapshot_date < range.end_date ORDER BY snapshot_date ASC LIMIT 200 | Q10: 0 | R10: PASS | U10: There is no risk score data available for the period from December to January, so the risk trend cannot be determined for that time. | V10: PASS | W10: 5 | X10: faithful=Y answers_question=Y contradiction=N sensitive_leak=N hallucinated_numbers=N | AA10: none | AF10: 5672 | AG10: 854/106 | AH10: 1 | AI10: PASS (no trace) | AJ10: ok | AM10: Worked example 8: bare month names crossing a year boundary resolve relative to CURRENT_DATE with >= 12, never > 12.
A11: S1.10 | B11: 1. Direct SQL generation | C11: userbehaviorbaseline | D11: sql | E11: easy | F11: new | H11: how many users are currently in the CRITICAL risk band | I11: sql | J11: sql | K11: SELECT COUNT(*) AS critical_users FROM dlp_core_userbehaviorbaseline WHERE risk_band_v2 = 'CRITICAL' | L11: SELECT user_id, username, weighted_risk_score_v2, risk_band_v2 FROM dlp_core_userbehaviorbaseline WHERE risk_band_v2 = 'CRITICAL' LIMIT 200 | M11: scalar | N11: PASS | P11: 1 | Q11: 17 | R11: PASS | U11: There are currently 17 users in the CRITICAL risk band, each with a risk score around 85 or higher. | V11: PASS | W11: 5 | X11: faithful=Y answers_question=Y contradiction=N sensitive_leak=N hallucinated_numbers=N | AA11: none | AF11: 4969 | AG11: 1004/136 | AH11: 1 | AI11: PASS (no trace) | AJ11: ok | AM11: Undated band question: the rolling baseline, the _v2 column, exact band named so no HIGH widening.
A12: S1.11 | B12: 1. Direct SQL generation | C12: userbehaviorbaseline | D12: sql | E12: easy | F12: new | H12: list all users who are currently high risk | I12: sql | J12: sql | K12: SELECT username FROM dlp_core_userbehaviorbaseline WHERE risk_band_v2 IN ('HIGH', 'CRITICAL') | L12: SELECT user_id, username, weighted_risk_score_v2, risk_band_v2 FROM dlp_core_userbehaviorbaseline WHERE risk_band_v2 IN ('HIGH', 'CRITICAL') ORDER BY weighted_risk_score_v2 DESC LIMIT 200 | M12: set_equal | N12: PASS | P12: 20 | Q12: 20 | R12: PASS | U12: There are 20 users who are currently high risk. Among them, 17 users have a critical risk level with scores mostly at 85 or above, including Pravin R with the highest score of 88. Three users have a high risk level with scores ranging from 65 to 68. | V12: WARN | W12: 2 | X12: faithful=Y answers_question=N contradiction=N sensitive_leak=N hallucinated_numbers=N | Y12: The user asked to list all users, but the answer only provides a summary and names one user. | AA12: none | AF12: 5469 | AG12: 1105/317 | AH12: 1 | AI12: PASS (judge warn) | AJ12: judge: answers_question, score 2 < 4; The user asked to list all users, but the answer only provides a summary and names one user. | AM12: Casual 'high risk' means HIGH and CRITICAL (b03d03e).
A13: S1.12 | B13: 1. Direct SQL generation | C13: userbehaviorbaseline | D13: sql | E13: easy | F13: new | H13: what is Pravin R's score driver | I13: sql | J13: decline | K13: SELECT score_driver_v2 FROM dlp_core_userbehaviorbaseline WHERE user_id = 14 | M13: scalar | U13: I couldn't find a user named "Pravin R's". Did you mean Pravin R? Let me know and I'll look them up. | V13: WARN | W13: 2 | X13: faithful=Y answers_question=N contradiction=N sensitive_leak=N hallucinated_numbers=N | Y13: The answer asks for clarification instead of providing Pravin R's score driver, even though the possessive wording is clear. | AA13: none | AB13: FAIL | AC13: sql does not filter on ['pravin', '14'] | AF13: 1828 | AG13: 634/408 | AH13: 0 | AI13: FAIL (no trace) | AJ13: outcome: got decline, expected ['sql']; anchor: sql does not filter on ['pravin', '14'] | AM13: _v2 column preference: score_driver_v2 (TREND/VOLUME/SPIKE), never the legacy score_driver.
A14: S1.13 | B14: 1. Direct SQL generation | C14: userbehaviorbaseline | D14: sql | E14: medium | F14: new | H14: which risk band has the most users right now | I14: sql | J14: sql | K14: SELECT risk_band_v2, COUNT(*) AS users FROM dlp_core_userbehaviorbaseline GROUP BY risk_band_v2 ORDER BY users DESC LIMIT 1 | L14: SELECT risk_band_v2, COUNT(*) AS user_count FROM dlp_core_userbehaviorbaseline GROUP BY risk_band_v2 ORDER BY user_count DESC LIMIT 1 | M14: subset | N14: PASS | P14: 1 | Q14: 1 | R14: PASS | U14: Right now, the CRITICAL risk band has 17 users, and this is the only risk band shown in the data. | V14: PASS | W14: 5 | X14: faithful=Y answers_question=Y contradiction=N sensitive_leak=N hallucinated_numbers=N | AA14: none | AF14: 4750 | AG14: 682/163 | AH14: 1 | AI14: PASS (no trace) | AJ14: ok | AM14: Grouped ranking on the baseline; the model may list every band, so the top row only has to be present.
A15: S1.14 | B15: 1. Direct SQL generation | C15: userbehaviorbaseline | D15: sql | E15: medium | F15: new | H15: how many users have a current risk score above 50 | I15: sql | J15: sql | K15: SELECT COUNT(*) AS users FROM dlp_core_userbehaviorbaseline WHERE weighted_risk_score_v2 > 50 | L15: SELECT COUNT(*) AS user_count_above_50 FROM dlp_core_userbehaviorbaseline WHERE weighted_risk_score_v2 > 50 LIMIT 200 | M15: scalar | N15: PASS | P15: 1 | Q15: 1 | R15: PASS | U15: There are 23 users who currently have a risk score above 50, indicating elevated risk levels based on their recent behavior and activity. | V15: WARN | W15: 4 | X15: faithful=N answers_question=Y contradiction=N sensitive_leak=N hallucinated_numbers=N | Y15: The count of 23 is supported, but the explanation about recent behavior and activity is not shown in the rows. | AA15: none | AF15: 4953 | AG15: 676/266 | AH15: 1 | AI15: PASS (judge warn) | AJ15: judge: faithful; The count of 23 is supported, but the explanation about recent behavior and activity is not shown in the rows. | AM15: Threshold on the current (_v2) score, never the legacy weighted_risk_score.
A16: S1.15 | B16: 1. Direct SQL generation | C16: userbehaviorbaseline, sfm.user | D16: sql | E16: hard | F16: new | H16: how many users are in each risk band per team | I16: sql | J16: sql | K16: SELECT u."TeamName", b.risk_band_v2, COUNT(*) AS users FROM dlp_core_userbehaviorbaseline b JOIN sfm."User" u ON u."UserId" = b.user_id GROUP BY u."TeamName", b.risk_band_v2 | L16: WITH user_risk AS ( SELECT user_id, username, risk_band_v2 FROM dlp_core_userbehaviorbaseline ), user_teams AS ( SELECT "UserId" AS user_id, "TeamName" AS team_name FROM sfm."User" ) SELECT ut.team_name, ur.risk_band_v2 AS risk_band, COUNT(*) AS user_count FROM user_risk ur JOIN user_teams ut ON ut.user_id = ur.user_id GROUP BY ut.team_name, ur.risk_band_v2 ORDER BY ut.team_name, ur.risk_band_v2 LIMIT 200 | M16: subset | N16: PASS | P16: 21 | Q16: 21 | R16: PASS | U16: There are 21 entries showing how many users fall into each risk band per team. For example, the API Team has 3 users in the CRITICAL band and 1 in MEDIUM, while the Exe Team has 2 CRITICAL and 3 SAFE users. Several teams, including "Other" and "Front End Team," have users spread across multiple risk bands from SAFE to CRITICAL. | V16: WARN | W16: 2 | X16: faithful=N answers_question=N contradiction=Y sensitive_leak=N hallucinated_numbers=N | Y16: The answer only gives examples instead of the counts for each risk band per team requested. | It implies Front End Team has users across the SAFE-to-CRITICAL range, but the rows show only HIGH and CRITICAL for that team. | AA16: none | AF16: 6265 | AG16: 1045/520 | AH16: 1 | AI16: PASS (judge warn) | AJ16: judge: faithful, answers_question, contradiction, score 2 < 4; The answer only gives examples instead of the counts for each risk band per team requested. | AM16: Current risk by team: join the one-row-per-user baseline straight to sfm."User" (no dedup needed).
A17: S1.16 | B17: 1. Direct SQL generation | C17: userbehaviorbaseline, tie | D17: sql | E17: medium | F17: new | H17: who has the highest average uploads per day | I17: sql | J17: sql | K17: SELECT username, avg_uploads_per_day FROM dlp_core_userbehaviorbaseline WHERE avg_uploads_per_day = (SELECT MAX(avg_uploads_per_day) FROM dlp_core_userbehaviorbaseline) | L17: SELECT user_id, username, avg_uploads_per_day FROM dlp_core_userbehaviorbaseline ORDER BY avg_uploads_per_day DESC LIMIT 1 | M17: subset | N17: PASS | P17: 1 | Q17: 1 | R17: PASS | U17: The user KdNetTestVM KdNetTestVM has the highest average uploads per day, with about 551.5 uploads each day. | V17: PASS | W17: 5 | X17: faithful=Y answers_question=Y contradiction=N sensitive_leak=N hallucinated_numbers=N | AA17: none | AF17: 4469 | AG17: 698/78 | AH17: 1 | AI17: PASS (no trace) | AJ17: ok | AM17: Superlative on a baseline column; tie-safe golden, the top row(s) must be present.
A18: S1.17 | B18: 1. Direct SQL generation | C18: dailyrisksnapshot, volatile | D18: sql | E18: easy | F18: new | H18: how many users had a risk snapshot yesterday | I18: sql | J18: sql | K18: SELECT COUNT(*) AS users FROM dlp_core_dailyrisksnapshot WHERE snapshot_date = CURRENT_DATE - 1 | L18: SELECT COUNT(*) AS user_count_with_risk_snapshot_yesterday FROM dlp_core_dailyrisksnapshot WHERE snapshot_date = CURRENT_DATE - INTERVAL '1 day' LIMIT 200 | M18: scalar | N18: PASS | P18: 1 | Q18: 1 | R18: PASS | U18: Yesterday, 47 users had a risk snapshot recorded. | V18: PASS | W18: 5 | X18: faithful=Y answers_question=Y contradiction=N sensitive_leak=N hallucinated_numbers=N | AA18: none | AF18: 5187 | AG18: 667/66 | AH18: 1 | AI18: PASS (no trace) | AJ18: ok | AM18: One row per user per day, so a single-day count needs no DISTINCT.
A19: S1.18 | B19: 1. Direct SQL generation | C19: dailyrisksnapshot, volatile | D19: sql | E19: easy | F19: new | H19: what was Pravin R's risk score yesterday | I19: sql | J19: decline | K19: SELECT weighted_risk_score_v2_d FROM dlp_core_dailyrisksnapshot WHERE user_id = 14 AND snapshot_date = CURRENT_DATE - 1 | M19: scalar | U19: I couldn't find a user named "Pravin R's". Did you mean Pravin R? Let me know and I'll look them up. | V19: WARN | W19: 2 | X19: faithful=N answers_question=N contradiction=N sensitive_leak=N hallucinated_numbers=N | Y19: The answer misinterprets the possessive as part of the user's name and does not provide the requested risk score. | The claim that no user named "Pravin R's" was found is not supported by any returned rows or SQL. | AA19: none | AB19: FAIL | AC19: sql does not filter on ['pravin', '14'] | AF19: 1672 | AG19: 635/487 | AH19: 0 | AI19: FAIL (no trace) | AJ19: outcome: got decline, expected ['sql']; anchor: sql does not filter on ['pravin', '14'] | AM19: A named day means the _d columns of dailyrisksnapshot, never the rolling baseline score.
A20: S1.19 | B20: 1. Direct SQL generation | C20: dailyrisksnapshot, kpi, volatile | D20: sql | E20: medium | F20: new | H20: how many users were high risk yesterday | I20: sql | J20: sql | K20: SELECT COUNT(*) AS high_risk_users FROM dlp_core_dailyrisksnapshot WHERE snapshot_date = CURRENT_DATE - 1 AND weighted_risk_score_v2_d >= 65 | L20: WITH yesterday_risk AS ( SELECT user_id, username, weighted_risk_score_v2_d FROM dlp_core_dailyrisksnapshot WHERE snapshot_date = CURRENT_DATE - INTERVAL '1 day' AND weighted_risk_score_v2_d > 0 ), high_risk_users AS ( SELECT user_id, username, weighted_risk_score_v2_d FROM yesterday_risk WHERE weighted_risk_score_v2_d >= 65 ), any_high_risk AS ( SELECT EXISTS (SELECT 1 FROM high_risk_users) AS has_high_risk ) SELECT COUNT(*) AS high_risk_user_count FROM ( SELECT user_id, username, weighted_risk_score_v2_d FROM high_risk_users UNION ALL SELECT user_id, username, weighted_risk_score_v2_d FROM yesterday_risk WHERE NOT (SELECT has_high_risk FROM any_high_risk) ORDER BY weighted_risk_score_v2_d DESC LIMIT 20 ) sub LIMIT 200 | M20: scalar | N20: PASS | P20: 1 | Q20: 1 | R20: PASS | U20: Yesterday, there were 3 users who reached a high risk level based on their peak risk scores for that day. | V20: WARN | W20: 4 | X20: faithful=N answers_question=Y contradiction=N sensitive_leak=N hallucinated_numbers=N | Y20: The count of 3 is supported, but the answer adds that it was based on peak risk scores, which is not shown in the returned rows. | AA20: none | AF20: 5594 | AG20: 859/258 | AH20: 1 | AI20: PASS (judge warn) | AJ20: judge: faithful; The count of 3 is supported, but the answer adds that it was based on peak risk scores, which is not shown in the returned rows. | AM20: Dashboard KPI: peak score >= 65 decides, never the band text (the band scale disagrees between 50 and 79).
A21: S1.20 | B21: 1. Direct SQL generation | C21: dailyrisksnapshot, kpi | D21: sql | E21: medium | F21: new | H21: what is the organization risk score this month | I21: sql | J21: sql | K21: WITH per_user AS (SELECT user_id, AVG(weighted_risk_score_v2_d) AS user_mean FROM dlp_core_dailyrisksnapshot WHERE snapshot_date >= date_trunc('month', CURRENT_DATE)::date AND snapshot_date <= CURRENT_DATE AND weighted_risk_score_v2_d > 0 GROUP BY user_id) SELECT ROUND(AVG(user_mean)::numeric, 2) AS org_risk_score FROM per_user | L21: WITH per_user AS ( SELECT user_id, AVG(weighted_risk_score_v2_d) AS user_mean FROM dlp_core_dailyrisksnapshot WHERE snapshot_date >= date_trunc('month', CURRENT_DATE) AND snapshot_date < date_trunc('month', CURRENT_DATE) + INTERVAL '1 month' AND weighted_risk_score_v2_d > 0 GROUP BY user_id ) SELECT ROUND(AVG(user_mean)::numeric, 2) AS organization_risk_score_this_month FROM per_user LIMIT 200 | M21: scalar | N21: PASS | P21: 1 | Q21: 1 | R21: PASS | U21: The organization's risk score for this month is 35.74, which means the overall risk level is moderate. This score reflects the average risk across all active users who had risky activity during the month, excluding days with no activity. | V21: WARN | W21: 4 | X21: faithful=N answers_question=Y contradiction=N sensitive_leak=N hallucinated_numbers=N | Y21: The qualitative label 'moderate' is not supported by the returned row or SQL thresholds. | AA21: none | AF21: 7407 | AG21: 801/356 | AH21: 1 | AI21: PASS (judge warn) | AJ21: judge: faithful; The qualitative label 'moderate' is not supported by the returned row or SQL thresholds. | AM21: Dashboard KPI: mean of per-user means, zero-score days excluded.
A22: S1.21 | B22: 1. Direct SQL generation | C22: dailyrisksnapshot, kpi | D22: sql | E22: hard | F22: new | H22: how many high risk users were there in august | I22: sql | J22: sql | K22: SELECT COUNT(*) AS high_risk_users FROM (SELECT user_id FROM dlp_core_dailyrisksnapshot WHERE snapshot_date >= make_date(EXTRACT(YEAR FROM CURRENT_DATE)::int, 8, 1) AND snapshot_date < make_date(EXTRACT(YEAR FROM CURRENT_DATE)::int, 9, 1) GROUP BY user_id HAVING MAX(weighted_risk_score_v2_d) >= 65) q | L22: WITH august_bounds AS ( SELECT CASE WHEN EXTRACT(MONTH FROM CURRENT_DATE) >= 8 THEN EXTRACT(YEAR FROM CURRENT_DATE) ELSE EXTRACT(YEAR FROM CURRENT_DATE) - 1 END::int AS august_year ), august_range AS ( SELECT make_date(august_year, 8, 1) AS start_date, make_date(august_year, 9, 1) AS end_date FROM august_bounds ), per_user_avg AS ( SELECT user_id, username, AVG(weighted_risk_score_v2_d) AS avg_risk_score FROM dlp_core_dailyrisksnapshot, august_range WHERE snapshot_date >= august_range.start_date AND snapshot_date < august_range.end_date AND weighted_risk_score_v2_d > 0 GROUP BY user_id, username ), flagged AS ( SELECT *, avg_risk_score >= 50 AS is_high_risk FROM per_user_avg ) SELECT COUNT(*) AS high_risk_user_count FROM flagged WHERE is_high_risk LIMIT 200 | M22: scalar | N22: PASS | P22: 1 | Q22: 1 | R22: FAIL | S22: sql must match />=\s*65/; sql must match /MAX\s*\(\s*(?:\w+\.)?weighted_risk_score_v2_d/ | U22: There were 5 users who reached a high risk level at least once during August. | V22: WARN | W22: 3 | X22: faithful=N answers_question=Y contradiction=Y sensitive_leak=N hallucinated_numbers=N | Y22: The answer misstates the criterion as users who reached high risk at least once, while the SQL counted users whose August average risk score was high. | AA22: none | AF22: 5859 | AG22: 869/382 | AH22: 0 | AI22: FAIL (no trace) | AJ22: structure: sql must match />=\s*65/; sql must match /MAX\s*\(\s*(?:\w+\.)?weighted_risk_score_v2_d/ | AM22: Dashboard KPI over a range: one user counts once if their PEAK day in the range reached 65. Finding 2026-09-21: the model used the 47416ef average-based rule (AVG >= 50) instead; the two prompt rules ('high risk users' KPI = peak >= 65 vs 'high risk user from X to now' = average >= 50) conflict for this wording. Both happened to give 5. Needs a decision on which rule wins.
A23: S1.22 | B23: 1. Direct SQL generation | C23: dailyrisksnapshot, kpi | D23: sql | E23: hard | F23: new | H23: show the risk score breakdown for this month | I23: sql | J23: sql | K23: SELECT ROUND(AVG(pct_anomaly_d)::numeric, 1) AS anomaly, ROUND(AVG(pct_sensitivity_d)::numeric, 1) AS sensitivity, ROUND(AVG(pct_behaviour_d)::numeric, 1) AS behaviour, ROUND(AVG(pct_destination_d)::numeric, 1) AS destination, ROUND(AVG(pct_context_d)::numeric, 1) AS context FROM dlp_core_dailyrisksnapshot WHERE snapshot_date >= date_trunc('month', CURRENT_DATE)::date AND snapshot_date <= CURRENT_DATE AND weighted_risk_score_v2_d > 0 | L23: SELECT AVG(pct_behaviour_d) AS avg_behaviour_percentage, AVG(pct_anomaly_d) AS avg_anomaly_percentage, AVG(pct_sensitivity_d) AS avg_sensitivity_percentage, AVG(pct_destination_d) AS avg_destination_percentage, AVG(pct_context_d) AS avg_context_percentage FROM dlp_core_dailyrisksnapshot WHERE snapshot_date >= date_trunc('month', CURRENT_DATE) AND snapshot_date < date_trunc('month', CURRENT_DATE) + INTERVAL '1 month' AND weighted_risk_score_v2_d > 0 LIMIT 200 | M23: set_equal | N23: PASS | P23: 1 | Q23: 1 | R23: PASS | U23: For this month, the risk score is mostly influenced by Destination Risk, which accounts for about 43% of the total. Anomaly Detection contributes around 29%, Data Sensitivity about 15%, Behaviour Deviation roughly 10%, and Context Score the smallest share at about 3.6%. | V23: PASS | W23: 5 | X23: faithful=Y answers_question=Y contradiction=N sensitive_leak=N hallucinated_numbers=N | AA23: none | AF23: 5531 | AG23: 865/126 | AH23: 1 | AI23: PASS (no trace) | AJ23: ok | AM23: Dashboard widget: a flat unweighted AVG of the five pct_* columns over the same rows the org score averages.
A24: S1.23 | B24: 1. Direct SQL generation | C24: dailyrisksnapshot, tie | D24: sql | E24: medium | F24: new | H24: on which day did Pravin R have the highest risk score | I24: sql | J24: sql | K24: SELECT snapshot_date, weighted_risk_score_v2_d FROM dlp_core_dailyrisksnapshot WHERE user_id = 14 AND weighted_risk_score_v2_d = (SELECT MAX(weighted_risk_score_v2_d) FROM dlp_core_dailyrisksnapshot WHERE user_id = 14) | L24: WITH user_days AS ( SELECT snapshot_date, weighted_risk_score_v2_d, risk_band_v2_d FROM dlp_core_dailyrisksnapshot WHERE username ILIKE '%Pravin R%' ), max_score AS ( SELECT MAX(weighted_risk_score_v2_d) AS highest_score FROM user_days ) SELECT snapshot_date, weighted_risk_score_v2_d, risk_band_v2_d FROM user_days WHERE weighted_risk_score_v2_d = (SELECT highest_score FROM max_score) ORDER BY snapshot_date ASC LIMIT 200 | M24: subset | N24: PASS | P24: 1 | Q24: 1 | R24: PASS | U24: Pravin R had his highest risk score of 100.0 on October 28, 2026, and that day was rated as HIGH risk. | V24: PASS | W24: 5 | X24: faithful=Y answers_question=Y contradiction=N sensitive_leak=N hallucinated_numbers=N | AA24: none | AB24: PASS | AF24: 5672 | AG24: 793/104 | AH24: 1 | AI24: PASS (no trace) | AJ24: ok | AM24: Peak day for one person: snapshot_date must be selected and the score must come from that same row.
A25: S1.24 | B25: 1. Direct SQL generation | C25: dlpevent, regression, commit:24eec36 | D25: sql | E25: medium | F25: new | H25: how many events happened on august 10, 2026 | I25: sql | J25: sql | L25: SELECT COUNT(*) AS total_events FROM dlp_core_dlpevent WHERE upload_start_time::date = '2026-08-10' LIMIT 200 | M25: nonempty | N25: PASS | Q25: 1 | R25: PASS | U25: On August 10, 2026, there were 530 file upload or transfer events recorded. | V25: PASS | W25: 5 | X25: faithful=Y answers_question=Y contradiction=N sensitive_leak=N hallucinated_numbers=N | AA25: none | AF25: 4641 | AG25: 667/323 | AH25: 1 | AI25: PASS (no trace) | AJ25: ok | AM25: 24eec36: a named day does not mean dailyrisksnapshot; event counts come from dlp_core_dlpevent or crunch."LandingLogsCrunched" (either is acceptable, so no golden).
A26: S1.25 | B26: 1. Direct SQL generation | C26: synclog | D26: sql | E26: easy | F26: new | H26: how many sync jobs have run in total | I26: sql | J26: sql | K26: SELECT COUNT(*) AS sync_jobs FROM dlp_core_synclog | L26: SELECT COUNT(*) AS total_sync_jobs_run FROM dlp_core_synclog LIMIT 200 | M26: scalar | N26: PASS | P26: 1 | Q26: 1 | R26: PASS | U26: A total of 6 sync jobs have run. | V26: PASS | W26: 5 | X26: faithful=Y answers_question=Y contradiction=N sensitive_leak=N hallucinated_numbers=N | AA26: none | AF26: 5313 | AG26: 641/65 | AH26: 1 | AI26: PASS (no trace) | AJ26: ok | AM26: Coverage for dlp_core_synclog (ingestion history, not user data). Finding 2026-09-21: Layer 1 NAME_PRERESOLVE_SUGGEST treated the word 'run' as a near-miss of 'Arun' (similarity 0.857 >= the 0.85 cutoff) and answered a did-you-mean without calling the model. This is the false positive CLAUDE.md warns about.
A27: S1.26 | B27: 1. Direct SQL generation | C27: dlpevent | D27: sql | E27: easy | F27: new | H27: how many of Pravin R's events were flagged as a new device | I27: sql | J27: decline | K27: SELECT COUNT(*) AS new_device_events FROM dlp_core_dlpevent WHERE user_id = 14 AND is_new_device_for_user = true | M27: scalar | U27: I couldn't find a user named "Pravin R's". Did you mean Pravin R? Let me know and I'll look them up. | V27: WARN | W27: 2 | X27: faithful=N answers_question=N contradiction=N sensitive_leak=N hallucinated_numbers=N | Y27: The question was unambiguous, but the answer asks for clarification instead of providing the count. | The claim that no user named "Pravin R's" was found is not supported by any returned rows. | AA27: none | AB27: FAIL | AC27: sql does not filter on ['pravin', '14'] | AF27: 1688 | AG27: 640/346 | AH27: 0 | AI27: FAIL (no trace) | AJ27: outcome: got decline, expected ['sql']; anchor: sql does not filter on ['pravin', '14'] | AM27: Single boolean flag on the per-event table.
A28: S1.27 | B28: 1. Direct SQL generation | C28: sfm.user | D28: sql | E28: easy | F28: new | H28: how many users are in the Exe Team | I28: sql | J28: sql | K28: SELECT COUNT(*) AS users FROM sfm."User" WHERE "TeamName" = 'Exe Team' | L28: SELECT COUNT(DISTINCT u."UserId") AS user_count FROM sfm."User" u WHERE u."TeamName" ILIKE '%Exe Team%' AND u."IsActive" = true AND u."IsDisabled" = false LIMIT 200 | M28: scalar | N28: PASS | P28: 1 | Q28: 1 | R28: PASS | U28: There are 6 users in the Exe Team. | V28: PASS | W28: 5 | X28: faithful=Y answers_question=Y contradiction=N sensitive_leak=N hallucinated_numbers=N | AA28: none | AB28: PASS | AF28: 4828 | AG28: 675/63 | AH28: 1 | AI28: PASS (no trace) | AJ28: ok | AM28: Team dimension lives on sfm."User"."TeamName", not dlp_core_dlpevent.department.
A29: S1.28 | B29: 1. Direct SQL generation | C29: dlpevent | D29: sql | E29: medium | F29: new | H29: how many events came from untrusted apps | I29: sql | J29: sql | K29: SELECT COUNT(*) AS untrusted_events FROM dlp_core_dlpevent WHERE trusted_app_flag = false | L29: SELECT COUNT(*) AS untrusted_app_event_count FROM dlp_core_dlpevent WHERE trusted_app_flag = false LIMIT 200 | M29: scalar | N29: PASS | P29: 1 | Q29: 1 | R29: PASS | U29: There were 57,833 events that came from untrusted applications. | V29: PASS | W29: 5 | X29: faithful=Y answers_question=Y contradiction=N sensitive_leak=N hallucinated_numbers=N | AA29: none | AF29: 4860 | AG29: 655/67 | AH29: 1 | AI29: PASS (no trace) | AJ29: ok | AM29: Boolean filter; 'untrusted' maps to trusted_app_flag = false.
A30: S1.29 | B30: 1. Direct SQL generation | C30: landinglogscrunched, kpi, volatile, regression, commit:b145709 | D30: sql | E30: easy | F30: new | H30: how many files were transferred today | I30: sql | J30: sql | K30: SELECT COUNT(*) AS total_files FROM crunch."LandingLogsCrunched" WHERE "ReceivedTime" >= CURRENT_DATE AND "ReceivedTime" < CURRENT_DATE + INTERVAL '1 day' | L30: SELECT COUNT(*) AS total_files, COUNT(*) FILTER (WHERE "PolicyAction" = 'Block') AS total_incidents_blocked FROM crunch."LandingLogsCrunched" WHERE "ReceivedTime" >= CURRENT_DATE AND "ReceivedTime" < CURRENT_DATE + INTERVAL '1 day' LIMIT 200 | M30: scalar | N30: PASS | P30: 1 | Q30: 1 | R30: PASS | U30: Today, a total of 437 files were transferred, and out of those, 413 were blocked incidents where policy violations stopped the transfer. | V30: PASS | W30: 5 | X30: faithful=Y answers_question=Y contradiction=N sensitive_leak=N hallucinated_numbers=N | AA30: none | AF30: 5453 | AG30: 708/128 | AH30: 1 | AI30: PASS (no trace) | AJ30: ok | AM30: Dashboard Total Files tile: COUNT(*) on LandingLogsCrunched by ReceivedTime (dlp_core_dlpevent gave 44 vs the real 50).
A31: S1.30 | B31: 1. Direct SQL generation | C31: landinglogscrunched, kpi, volatile, regression, commit:a5cb830 | D31: sql | E31: medium | F31: new | H31: how many incidents happened yesterday | I31: sql | J31: sql | K31: SELECT COUNT(*) AS total_files, COUNT(*) FILTER (WHERE "PolicyAction" = 'Block') AS total_incidents_blocked FROM crunch."LandingLogsCrunched" WHERE "ReceivedTime" >= CURRENT_DATE - INTERVAL '1 day' AND "ReceivedTime" < CURRENT_DATE | L31: SELECT COUNT(*) AS total_files, COUNT(*) FILTER (WHERE "PolicyAction" = 'Block') AS total_incidents_blocked FROM crunch."LandingLogsCrunched" WHERE "ReceivedTime" >= CURRENT_DATE - INTERVAL '1 day' AND "ReceivedTime" < CURRENT_DATE LIMIT 200 | M31: set_equal | N31: PASS | P31: 1 | Q31: 1 | R31: PASS | U31: Yesterday, there were 1,153 total files transferred, and out of those, 887 were incidents where the transfers were blocked due to policy violations. | V31: PASS | W31: 5 | X31: faithful=Y answers_question=Y contradiction=N sensitive_leak=N hallucinated_numbers=N | AA31: none | AF31: 4922 | AG31: 757/174 | AH31: 1 | AI31: PASS (no trace) | AJ31: ok | AM31: Both dashboard readings of 'incidents' in one query, each labelled.
A32: S1.31 | B32: 1. Direct SQL generation | C32: landinglogscrunched, kpi, volatile, regression, commit:b145709 | D32: sql | E32: easy | F32: new | H32: what is today's security score | I32: sql | J32: sql | K32: SELECT TRUNC(100 - (COUNT(*) FILTER (WHERE "PolicyAction" IN ('Block', 'Warn')))::numeric / NULLIF(COUNT(*), 0) * 100)::int AS security_score FROM crunch."LandingLogsCrunched" WHERE "ReceivedTime" >= CURRENT_DATE AND "ReceivedTime" < CURRENT_DATE + INTERVAL '1 day' | L32: SELECT TRUNC( 100 - ( COUNT(*) FILTER (WHERE "PolicyAction" IN ('Block', 'Warn') AND "ReceivedTime" >= CURRENT_DATE AND "ReceivedTime" < CURRENT_DATE + INTERVAL '1 day')::numeric / NULLIF(COUNT(*) FILTER (WHERE "ReceivedTime" >= CURRENT_DATE AND "ReceivedTime" < CURRENT_DATE + INTERVAL '1 day'), 0) * 100 ) )::int AS security_score FROM crunch."LandingLogsCrunched" WHERE "ReceivedTime" >= CURRENT_DATE AND "ReceivedTime" < CURRENT_DATE + INTERVAL '1 day' LIMIT 200 | M32: scalar | N32: PASS | P32: 1 | Q32: 1 | R32: PASS | U32: Today's security score is 5 out of 100, which means the organization's overall security posture is quite low and indicates a higher level of risk. This score is calculated by subtracting the proportion of blocked and warned policy actions from 100, so a lower score means more policy violations occurred today. | V32: PASS | W32: 5 | X32: faithful=Y answers_question=Y contradiction=N sensitive_leak=N hallucinated_numbers=N | AA32: none | AF32: 8360 | AG32: 818/204 | AH32: 1 | AI32: PASS (no trace) | AJ32: ok | AM32: Dashboard KPI: 100 - (block+warn)/total*100, TRUNCATED (::int rounded 56.86 to 57 when the dashboard showed 56).
A33: S1.32 | B33: 1. Direct SQL generation | C33: landinglogscrunched, kpi | D33: sql | E33: medium | F33: new | H33: what was the policy compliance percentage in august | I33: sql | J33: sql | K33: SELECT ROUND(100.0 * COUNT(*) FILTER (WHERE "PolicyAction" = 'Allow') / NULLIF(COUNT(*), 0), 2) AS compliance_pct FROM crunch."LandingLogsCrunched" WHERE "ReceivedTime" >= make_date(EXTRACT(YEAR FROM CURRENT_DATE)::int, 8, 1) AND "ReceivedTime" < make_date(EXTRACT(YEAR FROM CURRENT_DATE)::int, 9, 1) | L33: WITH bounds AS ( SELECT CASE WHEN EXTRACT(MONTH FROM CURRENT_DATE) >= 8 THEN EXTRACT(YEAR FROM CURRENT_DATE) ELSE EXTRACT(YEAR FROM CURRENT_DATE) - 1 END::int AS august_year ), range AS ( SELECT make_date(august_year, 8, 1) AS start_date, make_date(august_year, 9, 1) AS end_date FROM bounds ), counts AS ( SELECT COUNT(*) FILTER (WHERE "PolicyAction" = 'Allow') AS allow_count, COUNT(*) AS total_count FROM crunch."LandingLogsCrunched", range WHERE "ReceivedTime" >= range.start_date AND "ReceivedTime" < range.end_date ) SELECT ROUND(100.0 * allow_count::numeric / NULLIF(total_count, 0), 2) AS policy_compliance_percentage FROM counts LIMIT 200 | M33: scalar | N33: PASS | P33: 1 | Q33: 1 | R33: PASS | U33: The policy compliance percentage in August was 72.62%, meaning that about 72.62% of the data transfers followed the organization's policies during that month. | V33: PASS | W33: 5 | X33: faithful=Y answers_question=Y contradiction=N sensitive_leak=N hallucinated_numbers=N | AA33: none | AF33: 8157 | AG33: 852/123 | AH33: 1 | AI33: PASS (no trace) | AJ33: ok | AM33: Dashboard KPI: Allow / Total * 100 where Total is every row (Allow+Block+Warn+UnCovered).
A34: S1.33 | B34: 1. Direct SQL generation | C34: landinglogscrunched, kpi | D34: sql | E34: medium | F34: new | H34: which app has the most incidents | I34: sql | J34: sql | K34: SELECT "AppDeviceName", COUNT(*) AS incidents FROM crunch."LandingLogsCrunched" WHERE "IsDevice" = false GROUP BY "AppDeviceName" ORDER BY incidents DESC LIMIT 1 | L34: SELECT "AppDeviceName", COUNT(*) AS total_incidents FROM crunch."LandingLogsCrunched" WHERE "IsDevice" = false GROUP BY "AppDeviceName" ORDER BY total_incidents DESC LIMIT 1 | M34: subset | N34: PASS | P34: 1 | Q34: 1 | R34: PASS | U34: The app with the most incidents is One Drive, which had 30,938 total transfers recorded. This count includes all transfers, not just those blocked or flagged. | V34: PASS | W34: 5 | X34: faithful=Y answers_question=Y contradiction=N sensitive_leak=N hallucinated_numbers=N | AA34: none | AF34: 8391 | AG34: 702/340 | AH34: 1 | AI34: PASS (no trace) | AJ34: ok | AM34: Top Incident By Apps donut: IsDevice = false, EVERY row counted (adding a Block filter turned 3,191 into a wrong 477).
A35: S1.34 | B35: 1. Direct SQL generation | C35: landinglogscrunched, kpi | D35: sql | E35: medium | F35: new | H35: which device has the most incidents | I35: sql | J35: sql | K35: SELECT "AppDeviceName", COUNT(*) AS incidents FROM crunch."LandingLogsCrunched" WHERE "IsDevice" = true GROUP BY "AppDeviceName" ORDER BY incidents DESC LIMIT 1 | L35: SELECT l."MachineName", COUNT(*) AS total_incidents FROM crunch."LandingLogsCrunched" l WHERE l."IsDevice" = true GROUP BY l."MachineName" ORDER BY total_incidents DESC LIMIT 1 | M35: subset | N35: FAIL | O35: {"golden_rows": 1, "generated_rows": 1, "column_map": {"appdevicename": "machinename", "incidents": "total_incidents"}, "missing": 1, "extra": 1, "missing_examples": [["USB", 6375.0]], "extra_examples": [["INN111-PRAVINR", 4014.0]]} | P35: 1 | Q35: 1 | R35: PASS | U35: The device named INN111-PRAVINR has the highest number of incidents, with a total of 4,014 recorded. | V35: PASS | W35: 5 | X35: faithful=Y answers_question=Y contradiction=N sensitive_leak=N hallucinated_numbers=N | AA35: none | AF35: 6063 | AG35: 705/93 | AH35: 0 | AI35: FAIL (no trace) | AJ35: compare: subset: 1 golden row(s) missing, e.g. [('USB', 6375.0)] | AM35: Top Incident By Devices: the IsDevice = true tab (AppDeviceName such as USB), never mixed with apps. Finding 2026-09-21: the model grouped by MachineName (the endpoint machine) instead of AppDeviceName, answering with a PC name rather than the device channel.
A36: S1.35 | B36: 1. Direct SQL generation | C36: landinglogscrunched, sfm.user, kpi | D36: sql | E36: medium | F36: new | H36: which team has the most incidents | I36: sql | J36: sql | K36: SELECT u."TeamName", COUNT(*) AS incidents FROM crunch."LandingLogsCrunched" l JOIN sfm."User" u ON u."UserId" = l."UserID" GROUP BY u."TeamName" ORDER BY incidents DESC LIMIT 1 | L36: SELECT u."TeamName" AS team_name, COUNT(*) AS total_incidents FROM crunch."LandingLogsCrunched" l JOIN sfm."User" u ON u."UserId" = l."UserID" GROUP BY u."TeamName" ORDER BY total_incidents DESC LIMIT 1 | M36: subset | N36: PASS | P36: 1 | Q36: 1 | R36: PASS | U36: The Exe Team has the most incidents, with a total of 40,972 transfers recorded. This count includes all transfers, both allowed and blocked, as the term "incidents" here refers to total transfers rather than just policy violations. | V36: PASS | W36: 5 | X36: faithful=Y answers_question=Y contradiction=N sensitive_leak=N hallucinated_numbers=N | AA36: none | AF36: 5516 | AG36: 731/455 | AH36: 1 | AI36: PASS (no trace) | AJ36: ok | AM36: Grouped incidents by team: every transfer row counts, no PolicyAction filter.
A37: S1.36 | B37: 1. Direct SQL generation | C37: policy, kpi | D37: sql | E37: easy | F37: new | H37: how many active policies do we have | I37: sql | J37: sql | K37: SELECT COUNT(*) AS active_policies FROM dlp."Policy" WHERE "IsActive" = true | L37: SELECT COUNT(*) AS total_active_policies FROM dlp."Policy" WHERE "IsActive" = true LIMIT 200 | M37: scalar | N37: PASS | P37: 1 | Q37: 1 | R37: PASS | U37: There are 15 active policies currently in place. | V37: PASS | W37: 5 | X37: faithful=Y answers_question=Y contradiction=N sensitive_leak=N hallucinated_numbers=N | AA37: none | AF37: 4406 | AG37: 646/79 | AH37: 1 | AI37: PASS (no trace) | AJ37: ok | AM37: Dashboard Total Active Policies.
A38: S1.37 | B38: 1. Direct SQL generation | C38: endpoint, kpi | D38: sql | E38: easy | F38: new | H38: how many endpoints do we have | I38: sql | J38: sql | K38: SELECT COUNT(*) AS endpoints FROM sfm."Endpoint" WHERE "IsActive" = true AND "IsPrimaryUser" = true | L38: SELECT COUNT(*) AS total_active_primary_endpoints FROM sfm."Endpoint" WHERE "IsActive" = true AND "IsPrimaryUser" = true LIMIT 200 | M38: scalar | N38: PASS | P38: 1 | Q38: 1 | R38: PASS | U38: There are 42 active primary endpoints currently registered in the organization. | V38: PASS | W38: 5 | X38: faithful=Y answers_question=Y contradiction=N sensitive_leak=N hallucinated_numbers=N | AA38: none | AF38: 4765 | AG38: 658/164 | AH38: 1 | AI38: PASS (no trace) | AJ38: ok | AM38: Endpoint Coverage denominator: active AND primary-user endpoints, current state.
A39: S1.38 | B39: 1. Direct SQL generation | C39: endpointdailystatus, endpoint, kpi | D39: sql | E39: hard | F39: new | H39: what is the endpoint coverage this month | I39: sql | J39: sql | K39: WITH daily AS (SELECT eds."Date", COUNT(*) FILTER (WHERE eds."Status" <> 'Offline') AS healthy_d, COUNT(*) FILTER (WHERE eds."Status" = 'Offline') AS offline_d FROM dlp."EndpointDailyStatus" eds JOIN sfm."Endpoint" e ON e."EndpointId" = eds."EndpointId" WHERE e."IsActive" AND e."IsPrimaryUser" AND eds."Date" >= date_trunc('month', CURRENT_DATE)::date AND eds."Date" <= CURRENT_DATE GROUP BY eds."Date") SELECT ROUND(100.0 * SUM(healthy_d)::numeric / NULLIF(SUM(healthy_d + offline_d), 0), 2) AS healthy_pct FROM daily | L39: WITH daily AS ( SELECT eds."Date", COUNT(*) FILTER (WHERE eds."Status" <> 'Offline') AS healthy_d, COUNT(*) FILTER (WHERE eds."Status" = 'Offline') AS offline_d FROM dlp."EndpointDailyStatus" eds JOIN sfm."Endpoint" e ON e."EndpointId" = eds."EndpointId" WHERE e."IsActive" AND e."IsPrimaryUser" AND eds."Date" >= date_trunc('month', CURRENT_DATE) AND eds."Date" < date_trunc('month', CURRENT_DATE) + INTERVAL '1 month' GROUP BY eds."Date" ) SELECT ROUND(100.0 * SUM(healthy_d)::numeric / NULLIF(SUM(healthy_d + offline_d), 0), 2) AS healthy_pct, ROUND(100.0 * SUM(offline_d)::numeric / NULLIF(SUM(healthy_d + offline_d), 0), 2) AS offline_pct FROM daily LIMIT 200 | M39: scalar | N39: PASS | P39: 1 | Q39: 1 | R39: PASS | U39: The endpoint coverage this month shows that about 26.76% of endpoints were healthy, while 73.24% were offline. This means most endpoints were offline during this period. | V39: PASS | W39: 5 | X39: faithful=Y answers_question=Y contradiction=N sensitive_leak=N hallucinated_numbers=N | AA39: none | AF39: 6281 | AG39: 906/95 | AH39: 1 | AI39: PASS (no trace) | AJ39: ok | AM39: Dashboard Endpoint Coverage: ratio of sums over the range (a weighted average of daily ratios), never a single day's snapshot.
A40: S1.39 | B40: 1. Direct SQL generation | C40: dailyrisksnapshot, landinglogscrunched, kpi, regression, commit:1d780b6 | D40: sql | E40: hard | F40: new | H40: what are the total high risk violations and total violations this month | I40: sql | J40: sql | K40: WITH q AS (SELECT user_id FROM dlp_core_dailyrisksnapshot WHERE snapshot_date >= date_trunc('month', CURRENT_DATE)::date AND snapshot_date <= CURRENT_DATE GROUP BY user_id HAVING MAX(weighted_risk_score_v2_d) >= 65) SELECT (SELECT COALESCE(SUM(high_risk_event_count_d), 0) FROM dlp_core_dailyrisksnapshot WHERE user_id IN (SELECT user_id FROM q) AND snapshot_date >= date_trunc('month', CURRENT_DATE)::date AND snapshot_date <= CURRENT_DATE) AS total_high_risk_violation, (SELECT COUNT(*) FROM crunch."LandingLogsCrunched" WHERE "UserID" IN (SELECT user_id FROM q) AND "PolicyAction" IN ('Block', 'Warn') AND "ReceivedTime" >= date_trunc('month', CURRENT_DATE) AND "ReceivedTime" < date_trunc('month', CURRENT_DATE) + INTERVAL '1 month') AS total_violations | L40: WITH date_bounds AS ( SELECT date_trunc('month', CURRENT_DATE) AS start_date, date_trunc('month', CURRENT_DATE) + INTERVAL '1 month' AS end_date ), high_risk_users AS ( SELECT user_id FROM dlp_core_dailyrisksnapshot, date_bounds WHERE snapshot_date >= date_bounds.start_date AND snapshot_date < date_bounds.end_date GROUP BY user_id HAVING MAX(weighted_risk_score_v2_d) >= 65 ), high_risk_violations AS ( SELECT SUM(high_risk_event_count_d) AS total_high_risk_violations FROM dlp_core_dailyrisksnapshot, date_bounds WHERE snapshot_date >= date_bounds.start_date AND snapshot_date < date_bounds.end_date AND user_id IN (SELECT user_id FROM high_risk_users) ), total_violations AS ( SELECT COUNT(*) AS total_violations FROM crunch."LandingLogsCrunched", date_bounds WHERE "UserID" IN (SELECT user_id FROM high_risk_users) AND "PolicyAction" IN ('Block', 'Warn') AND "ReceivedTime" >= date_bounds.start_date AND "ReceivedTime" < date_bounds.end_date ) SELECT COALESCE(hrv.total_high_risk_violations, 0) AS total_high_risk_violations_this_month, COALESCE(tv.total_violations, 0) AS total_violations_this_month FROM high_risk_violations hrv CROSS JOIN total_violations tv LIMIT 200 | M40: set_equal | N40: PASS | P40: 1 | Q40: 1 | R40: PASS | U40: This month, there have been 158 total high risk violations, which counts the most serious policy breaches by high-risk users, and 6,395 total violations overall, including all policy blocks and warnings across the organization. | V40: WARN | W40: 2 | X40: faithful=N answers_question=Y contradiction=Y sensitive_leak=N hallucinated_numbers=N | Y40: The 6,395 total violations are scoped to high-risk users in the SQL, not across the entire organization. | AA40: none | AF40: 7094 | AG40: 1061/338 | AH40: 1 | AI40: PASS (judge warn) | AJ40: judge: faithful, contradiction, score 2 < 4; The 6,395 total violations are scoped to high-risk users in the SQL, not across the entire organization. | AM40: High Risk Users card: both counters scoped to qualifying users, never an unscoped Block+Warn count across everyone.
...

Sheet Summary
A1: Section | B1: Cases | C1: Pass | D1: Fail | E1: Skip | F1: Manual | G1: Error | H1: Regressions | I1: Judge avg score | J1: Avg latency ms
A2: 1. Direct SQL generation | B2: =COUNTIF(Results!$B$2:$B$121,$A2) | C2: =COUNTIFS(Results!$B$2:$B$121,$A2,Results!$AI$2:$AI$121,"PASS*") | D2: =COUNTIFS(Results!$B$2:$B$121,$A2,Results!$AI$2:$AI$121,"FAIL*") | E2: =COUNTIFS(Results!$B$2:$B$121,$A2,Results!$AI$2:$AI$121,"SKIP") | F2: =COUNTIFS(Results!$B$2:$B$121,$A2,Results!$AI$2:$AI$121,"MANUAL") | G2: =COUNTIFS(Results!$B$2:$B$121,$A2,Results!$AI$2:$AI$121,"ERROR") | H2: =COUNTIFS(Results!$B$2:$B$121,$A2,Results!$AL$2:$AL$121,"REGRESSION") | I2: =IFERROR(AVERAGEIFS(Results!$W$2:$W$121,Results!$B$2:$B$121,$A2),"") | J2: =IFERROR(AVERAGEIFS(Results!$AF$2:$AF$121,Results!$B$2:$B$121,$A2),"")
A3: 2. SQL regressions | B3: =COUNTIF(Results!$B$2:$B$121,$A3) | C3: =COUNTIFS(Results!$B$2:$B$121,$A3,Results!$AI$2:$AI$121,"PASS*") | D3: =COUNTIFS(Results!$B$2:$B$121,$A3,Results!$AI$2:$AI$121,"FAIL*") | E3: =COUNTIFS(Results!$B$2:$B$121,$A3,Results!$AI$2:$AI$121,"SKIP") | F3: =COUNTIFS(Results!$B$2:$B$121,$A3,Results!$AI$2:$AI$121,"MANUAL") | G3: =COUNTIFS(Results!$B$2:$B$121,$A3,Results!$AI$2:$AI$121,"ERROR") | H3: =COUNTIFS(Results!$B$2:$B$121,$A3,Results!$AL$2:$AL$121,"REGRESSION") | I3: =IFERROR(AVERAGEIFS(Results!$W$2:$W$121,Results!$B$2:$B$121,$A3),"") | J3: =IFERROR(AVERAGEIFS(Results!$AF$2:$AF$121,Results!$B$2:$B$121,$A3),"")
A4: 3. Reasoning and follow-ups | B4: =COUNTIF(Results!$B$2:$B$121,$A4) | C4: =COUNTIFS(Results!$B$2:$B$121,$A4,Results!$AI$2:$AI$121,"PASS*") | D4: =COUNTIFS(Results!$B$2:$B$121,$A4,Results!$AI$2:$AI$121,"FAIL*") | E4: =COUNTIFS(Results!$B$2:$B$121,$A4,Results!$AI$2:$AI$121,"SKIP") | F4: =COUNTIFS(Results!$B$2:$B$121,$A4,Results!$AI$2:$AI$121,"MANUAL") | G4: =COUNTIFS(Results!$B$2:$B$121,$A4,Results!$AI$2:$AI$121,"ERROR") | H4: =COUNTIFS(Results!$B$2:$B$121,$A4,Results!$AL$2:$AL$121,"REGRESSION") | I4: =IFERROR(AVERAGEIFS(Results!$W$2:$W$121,Results!$B$2:$B$121,$A4),"") | J4: =IFERROR(AVERAGEIFS(Results!$AF$2:$AF$121,Results!$B$2:$B$121,$A4),"")
